<?xml version='1.0'?>
<robot name="my_robot" xmlns:xacro="http://www.ros.org/wiki/xacro">
  <material name="blue">
    <color rgba="0 0 1 1"/>
  </material>
  <material name="green">
    <color rgba="0 1 0 1"/>
  </material>
  <material name="grey">
    <color rgba="0.7 0.7 0.7 1"/>
  </material>
  <material name="red">
    <color rgba="1 0 0 1"/>
  </material>
  <material name="black">
    <color rgba="0 0 0 1"/>
  </material>
  <material name="yellow">
    <color rgba="1 1 0 1"/>
  </material>
  <material name="white">
    <color rgba="1 1 1 1"/>
  </material>
  <material name="top_cylinder_blue_material">
    <color rgba="0 0 1 1"/>
  </material>
  <xacro:include filename="$(find my_robot)/urdf/my_robot.gazebo" />
  <link name="robot_footprint"></link>
  <joint name="robot_footprint_joint" type="fixed">
    <origin xyz="0 0 0" rpy="0 0 0" />
    <parent link="robot_footprint"/>
    <child link="chassis" />
  </joint>
  <link name='chassis'>
    <pose>0 0 0.06 0 0 0</pose>
    <inertial>
      <mass value="15.0"/>
      <origin xyz="0.0 0 0" rpy="0 0 0"/>
      <inertia
        ixx="0.1" ixy="0" ixz="0"
        iyy="0.1" iyz="0"
        izz="0.1"
      />
    </inertial>
    <collision name='collision'>
      <origin xyz="0 0 0" rpy="0 0 0"/>
      <geometry>
        <box size=".45 .33 .06"/>
      </geometry>
    </collision>
    <visual name='chassis_visual_base'>
      <origin xyz="0 0 0" rpy="0 0 0"/>
      <geometry>
        <box size=".45 .33 .06"/>
      </geometry>
      <material name="yellow"/>
    </visual>
    <collision name='back_caster_collision'>
      <origin xyz="-0.15 0 -0.025" rpy="0 0 0"/>
      <geometry>
        <sphere radius="0.035"/>
      </geometry>
    </collision>
    <visual name='back_caster_visual'>
      <origin xyz="-0.15 0 -0.025" rpy="0 0 0"/>
      <geometry>
        <sphere radius="0.035"/>
      </geometry>
      <material name="grey"/>
    </visual>
    <collision name='front_caster_collision'>
      <origin xyz="0.15 0 -0.025" rpy="0 0 0"/>
      <geometry>
        <sphere radius="0.035"/>
      </geometry>
    </collision>
    <visual name='front_caster_visual'>
      <origin xyz="0.15 0 -0.025" rpy="0 0 0"/>
      <geometry>
        <sphere radius="0.035"/>
      </geometry>
      <material name="grey"/>
    </visual>
  </link>
  <link name='top_cylinder_link'>
    <inertial>
      <mass value="0.1"/>
      <origin xyz="0 0 0" rpy="0 0 0"/>
      <inertia
        ixx="1e-6" ixy="0" ixz="0"
        iyy="1e-6" iyz="0"
        izz="1e-6"
      />
    </inertial>
    <collision>
      <origin xyz="0 0 0" rpy="0 0 0"/>
      <geometry>
        <cylinder radius="0.08" length="0.05"/>
      </geometry>
    </collision>
    <visual>
      <origin xyz="0 0 0" rpy="0 0 0"/>
      <geometry>
        <cylinder radius="0.08" length="0.05"/>
      </geometry>
      <material name="top_cylinder_blue_material"/>
    </visual>
  </link>
  <joint name="top_cylinder_joint" type="fixed">
    <origin xyz="0 0 0.055" rpy="0 0 0"/>
    <parent link="chassis"/>
    <child link="top_cylinder_link"/>
  </joint>
  <link name='left_wheel'>
    <inertial>
      <mass value="5"/>
      <origin xyz="0 0 0" rpy="0 1.5707 1.5707"/>
      <inertia
        ixx="0.1" ixy="0" ixz="0"
        iyy="0.1" iyz="0"
        izz="0.1"
      />
    </inertial>
    <collision>
      <origin xyz="0 0 0" rpy="0 1.5707 1.5707"/>
      <geometry>
        <cylinder radius="0.08" length="0.025"/>
      </geometry>
    </collision>
    <visual>
      <origin xyz="0 0 0" rpy="0 1.5707 1.5707"/>
      <geometry>
        <cylinder radius="0.08" length="0.025"/>
      </geometry>
      <material name="green"/>
    </visual>
  </link>
  <link name='right_wheel'>
    <inertial>
      <mass value="5"/>
      <origin xyz="0 0 0" rpy="0 1.5707 1.5707"/>
      <inertia
        ixx="0.1" ixy="0" ixz="0"
        iyy="0.1" iyz="0"
        izz="0.1"
      />
    </inertial>
    <collision>
      <origin xyz="0 0 0" rpy="0 1.5707 1.5707"/>
      <geometry>
        <cylinder radius="0.08" length="0.025"/>
      </geometry>
    </collision>
    <visual>
      <origin xyz="0 0 0" rpy="0 1.5707 1.5707"/>
      <geometry>
        <cylinder radius="0.08" length="0.025"/>
      </geometry>
      <material name="green"/>
    </visual>
  </link>
  <joint type="continuous" name="left_wheel_joint">
    <origin xyz="0 0.165 0.02" rpy="0 0 0"/>
    <child link="left_wheel"/>
    <parent link="chassis"/>
    <axis xyz="0 1 0" rpy="0 0 0"/>
    <limit effort="10000" velocity="1000"/>
    <dynamics damping="1.0" friction="1.0"/>
  </joint>
  <joint type="continuous" name="right_wheel_joint">
    <origin xyz="0 -0.165 0.02" rpy="0 0 0"/>
    <child link="right_wheel"/>
    <parent link="chassis"/>
    <axis xyz="0 1 0" rpy="0 0 0"/>
    <limit effort="10000" velocity="1000"/>
    <dynamics damping="1.0" friction="1.0"/>
  </joint>
  <link name='camera'>
    <inertial>
      <mass value="0.1"/>
      <origin xyz="0 0 0" rpy="0 0 0"/>
      <inertia
        ixx="1e-6" ixy="0" ixz="0"
        iyy="1e-6" iyz="0"
        izz="1e-6"
      />
    </inertial>
    <collision>
      <origin xyz="0 0 0" rpy="0 0 0"/>
      <geometry>
        <box size="0.06 0.06 0.06"/>
      </geometry>
    </collision>
    <visual>
      <origin xyz="0 0 0" rpy="0 0 0"/>
      <geometry>
        <box size="0.06 0.06 0.06"/>
      </geometry>
      <material name="red"/>
    </visual>
  </link>
  <joint name="camera_joint" type="fixed">
    <origin xyz="0.225 0 0.03" rpy="0 0 0"/>
    <parent link="chassis"/>
    <child link="camera"/>
    <axis xyz="0 1 0"/>
  </joint>
  <joint name="camera_optical_joint" type="fixed">
    <origin xyz="0 0 0" rpy="-1.5707 0 -1.5707"/>
    <parent link="camera"/>
    <child link="camera_link_optical"/>
  </joint>
  <link name="camera_link_optical">
  </link>
  <link name='hokuyo'>
    <inertial>
      <mass value="1e-5"/>
      <origin xyz="0 0 0" rpy="0 0 0"/>
      <inertia
        ixx="1e-6" ixy="0" ixz="0"
        iyy="1e-6" iyz="0"
        izz="1e-6"
      />
    </inertial>
    <collision>
      <origin xyz="0 0 0" rpy="0 0 0"/>
      <geometry>
        <box size="0.1 0.1 0.1"/>
      </geometry>
    </collision>
    <visual>
      <origin xyz="0 0 0" rpy="0 0 0"/>
      <geometry>
        <mesh filename="package://my_robot/meshes/hokuyo.dae"/>
      </geometry>
      <material name="black"/>
    </visual>
  </link>
  <joint name="hokuyo_joint" type="fixed">
    <origin xyz="0.15 0 0.085" rpy="0 0 0"/>
    <parent link="chassis"/>
    <child link="hokuyo"/>
    <axis xyz="0 1 0"/>
  </joint>
  <gazebo reference="chassis">
    <material>Gazebo/Yellow</material>
  </gazebo>
  <gazebo reference="top_cylinder_link">
    <material>Gazebo/Blue</material>
  </gazebo>
  <gazebo reference="left_wheel">
    <material>Gazebo/Green</material>
  </gazebo>
  <gazebo reference="right_wheel">
    <material>Gazebo/Green</material>
  </gazebo>
  <gazebo reference="front_caster">
    <material>Gazebo/Grey</material>
  </gazebo>
  <gazebo reference="back_caster">
    <material>Gazebo/Grey</material>
  </gazebo>
  <gazebo reference="camera">
    <material>Gazebo/Red</material>
  </gazebo>
  <gazebo reference="hokuyo">
    <material>Gazebo/Black</material>
  </gazebo>
</robot>